[2025-06-15 17:35:24,302] {taskinstance.py:896} INFO - Dependencies all met for <TaskInstance: Job_dag.data_ingestion 2025-06-15T17:34:20.659968+00:00 [queued]>
[2025-06-15 17:35:24,386] {taskinstance.py:896} INFO - Dependencies all met for <TaskInstance: Job_dag.data_ingestion 2025-06-15T17:34:20.659968+00:00 [queued]>
[2025-06-15 17:35:24,387] {taskinstance.py:1087} INFO - 
--------------------------------------------------------------------------------
[2025-06-15 17:35:24,387] {taskinstance.py:1088} INFO - Starting attempt 2 of 2
[2025-06-15 17:35:24,387] {taskinstance.py:1089} INFO - 
--------------------------------------------------------------------------------
[2025-06-15 17:35:24,420] {taskinstance.py:1107} INFO - Executing <Task(PythonOperator): data_ingestion> on 2025-06-15T17:34:20.659968+00:00
[2025-06-15 17:35:24,425] {standard_task_runner.py:52} INFO - Started process 80 to run task
[2025-06-15 17:35:24,429] {standard_task_runner.py:76} INFO - Running: ['***', 'tasks', 'run', 'Job_dag', 'data_ingestion', '2025-06-15T17:34:20.659968+00:00', '--job-id', '64', '--pool', 'default_pool', '--raw', '--subdir', 'DAGS_FOLDER/churn_dag.py', '--cfg-path', '/tmp/tmp_zrapwlo', '--error-file', '/tmp/tmpmblwtv33']
[2025-06-15 17:35:24,429] {standard_task_runner.py:77} INFO - Job 64: Subtask data_ingestion
[2025-06-15 17:35:24,650] {logging_mixin.py:104} INFO - Running <TaskInstance: Job_dag.data_ingestion 2025-06-15T17:34:20.659968+00:00 [running]> on host d5b30d77de00
[2025-06-15 17:35:24,976] {taskinstance.py:1302} INFO - Exporting the following env vars:
AIRFLOW_CTX_DAG_EMAIL=***@example.com
AIRFLOW_CTX_DAG_OWNER=***
AIRFLOW_CTX_DAG_ID=Job_dag
AIRFLOW_CTX_TASK_ID=data_ingestion
AIRFLOW_CTX_EXECUTION_DATE=2025-06-15T17:34:20.659968+00:00
AIRFLOW_CTX_DAG_RUN_ID=manual__2025-06-15T17:34:20.659968+00:00
[2025-06-15 17:35:24,982] {taskinstance.py:1501} ERROR - Task failed with exception
Traceback (most recent call last):
  File "/home/airflow/.local/lib/python3.6/site-packages/airflow/models/taskinstance.py", line 1157, in _run_raw_task
    self._prepare_and_execute_task_with_callbacks(context, task)
  File "/home/airflow/.local/lib/python3.6/site-packages/airflow/models/taskinstance.py", line 1331, in _prepare_and_execute_task_with_callbacks
    result = self._execute_task(context, task_copy)
  File "/home/airflow/.local/lib/python3.6/site-packages/airflow/models/taskinstance.py", line 1361, in _execute_task
    result = task_copy.execute(context=context)
  File "/home/airflow/.local/lib/python3.6/site-packages/airflow/operators/python.py", line 150, in execute
    return_value = self.execute_callable()
  File "/home/airflow/.local/lib/python3.6/site-packages/airflow/operators/python.py", line 161, in execute_callable
    return self.python_callable(*self.op_args, **self.op_kwargs)
  File "/opt/airflow/dags/Staging_upload.py", line 13, in ingestionFunc
    port="6546"
  File "/home/airflow/.local/lib/python3.6/site-packages/psycopg2/__init__.py", line 122, in connect
    conn = _connect(dsn, connection_factory=connection_factory, **kwasync)
psycopg2.OperationalError: could not connect to server: Connection refused
	Is the server running on host "host.docker.internal" (192.168.65.254) and accepting
	TCP/IP connections on port 6546?
could not connect to server: Network is unreachable
	Is the server running on host "host.docker.internal" (fdc4:f303:9324::254) and accepting
	TCP/IP connections on port 6546?

[2025-06-15 17:35:24,985] {taskinstance.py:1551} INFO - Marking task as FAILED. dag_id=Job_dag, task_id=data_ingestion, execution_date=20250615T173420, start_date=20250615T173524, end_date=20250615T173524
[2025-06-15 17:35:25,066] {local_task_job.py:151} INFO - Task exited with return code 1
