[2025-06-15 18:03:59,364] {taskinstance.py:896} INFO - Dependencies all met for <TaskInstance: Job_dag.data_ingestion 2025-06-15T18:03:57.493230+00:00 [queued]>
[2025-06-15 18:03:59,415] {taskinstance.py:896} INFO - Dependencies all met for <TaskInstance: Job_dag.data_ingestion 2025-06-15T18:03:57.493230+00:00 [queued]>
[2025-06-15 18:03:59,415] {taskinstance.py:1087} INFO - 
--------------------------------------------------------------------------------
[2025-06-15 18:03:59,415] {taskinstance.py:1088} INFO - Starting attempt 1 of 2
[2025-06-15 18:03:59,415] {taskinstance.py:1089} INFO - 
--------------------------------------------------------------------------------
[2025-06-15 18:03:59,431] {taskinstance.py:1107} INFO - Executing <Task(PythonOperator): data_ingestion> on 2025-06-15T18:03:57.493230+00:00
[2025-06-15 18:03:59,433] {standard_task_runner.py:52} INFO - Started process 115 to run task
[2025-06-15 18:03:59,435] {standard_task_runner.py:76} INFO - Running: ['***', 'tasks', 'run', 'Job_dag', 'data_ingestion', '2025-06-15T18:03:57.493230+00:00', '--job-id', '75', '--pool', 'default_pool', '--raw', '--subdir', 'DAGS_FOLDER/churn_dag.py', '--cfg-path', '/tmp/tmpfcsb7t5d', '--error-file', '/tmp/tmp4ok5tm9a']
[2025-06-15 18:03:59,435] {standard_task_runner.py:77} INFO - Job 75: Subtask data_ingestion
[2025-06-15 18:03:59,575] {logging_mixin.py:104} INFO - Running <TaskInstance: Job_dag.data_ingestion 2025-06-15T18:03:57.493230+00:00 [running]> on host 08f2436b3465
[2025-06-15 18:03:59,800] {taskinstance.py:1302} INFO - Exporting the following env vars:
AIRFLOW_CTX_DAG_EMAIL=***@example.com
AIRFLOW_CTX_DAG_OWNER=***
AIRFLOW_CTX_DAG_ID=Job_dag
AIRFLOW_CTX_TASK_ID=data_ingestion
AIRFLOW_CTX_EXECUTION_DATE=2025-06-15T18:03:57.493230+00:00
AIRFLOW_CTX_DAG_RUN_ID=manual__2025-06-15T18:03:57.493230+00:00
[2025-06-15 18:03:59,813] {logging_mixin.py:104} INFO - Conection Testing123
[2025-06-15 18:03:59,813] {logging_mixin.py:104} INFO - <connection object at 0x7fffb513e688; dsn: 'user=myuser password=xxx dbname=cust_churn_stg host=host.docker.internal port=6543', closed: 0>
[2025-06-15 18:03:59,813] {taskinstance.py:1501} ERROR - Task failed with exception
Traceback (most recent call last):
  File "/home/airflow/.local/lib/python3.6/site-packages/airflow/models/taskinstance.py", line 1157, in _run_raw_task
    self._prepare_and_execute_task_with_callbacks(context, task)
  File "/home/airflow/.local/lib/python3.6/site-packages/airflow/models/taskinstance.py", line 1331, in _prepare_and_execute_task_with_callbacks
    result = self._execute_task(context, task_copy)
  File "/home/airflow/.local/lib/python3.6/site-packages/airflow/models/taskinstance.py", line 1361, in _execute_task
    result = task_copy.execute(context=context)
  File "/home/airflow/.local/lib/python3.6/site-packages/airflow/operators/python.py", line 150, in execute
    return_value = self.execute_callable()
  File "/home/airflow/.local/lib/python3.6/site-packages/airflow/operators/python.py", line 161, in execute_callable
    return self.python_callable(*self.op_args, **self.op_kwargs)
  File "/opt/airflow/dags/Staging_upload.py", line 24, in ingestionFunc
    with open('customer_churn_data.csv', 'r') as f:
FileNotFoundError: [Errno 2] No such file or directory: 'customer_churn_data.csv'
[2025-06-15 18:03:59,816] {taskinstance.py:1551} INFO - Marking task as UP_FOR_RETRY. dag_id=Job_dag, task_id=data_ingestion, execution_date=20250615T180357, start_date=20250615T180359, end_date=20250615T180359
[2025-06-15 18:03:59,905] {local_task_job.py:151} INFO - Task exited with return code 1
