[2025-06-15 16:51:55,887] {taskinstance.py:896} INFO - Dependencies all met for <TaskInstance: Job_dag.data_ingestion 2025-03-05T00:00:00+00:00 [queued]>
[2025-06-15 16:51:55,967] {taskinstance.py:896} INFO - Dependencies all met for <TaskInstance: Job_dag.data_ingestion 2025-03-05T00:00:00+00:00 [queued]>
[2025-06-15 16:51:55,969] {taskinstance.py:1087} INFO - 
--------------------------------------------------------------------------------
[2025-06-15 16:51:55,970] {taskinstance.py:1088} INFO - Starting attempt 2 of 2
[2025-06-15 16:51:55,971] {taskinstance.py:1089} INFO - 
--------------------------------------------------------------------------------
[2025-06-15 16:51:55,996] {taskinstance.py:1107} INFO - Executing <Task(PythonOperator): data_ingestion> on 2025-03-05T00:00:00+00:00
[2025-06-15 16:51:56,005] {standard_task_runner.py:52} INFO - Started process 295 to run task
[2025-06-15 16:51:56,011] {standard_task_runner.py:76} INFO - Running: ['***', 'tasks', 'run', 'Job_dag', 'data_ingestion', '2025-03-05T00:00:00+00:00', '--job-id', '19', '--pool', 'default_pool', '--raw', '--subdir', 'DAGS_FOLDER/churn_dag.py', '--cfg-path', '/tmp/tmp4cmsnzjr', '--error-file', '/tmp/tmpo7iyr9u3']
[2025-06-15 16:51:56,011] {standard_task_runner.py:77} INFO - Job 19: Subtask data_ingestion
[2025-06-15 16:51:56,247] {logging_mixin.py:104} INFO - Running <TaskInstance: Job_dag.data_ingestion 2025-03-05T00:00:00+00:00 [running]> on host a7887df5758f
[2025-06-15 16:51:56,542] {taskinstance.py:1302} INFO - Exporting the following env vars:
AIRFLOW_CTX_DAG_EMAIL=***@example.com
AIRFLOW_CTX_DAG_OWNER=***
AIRFLOW_CTX_DAG_ID=Job_dag
AIRFLOW_CTX_TASK_ID=data_ingestion
AIRFLOW_CTX_EXECUTION_DATE=2025-03-05T00:00:00+00:00
AIRFLOW_CTX_DAG_RUN_ID=scheduled__2025-03-05T00:00:00+00:00
[2025-06-15 16:51:56,547] {taskinstance.py:1501} ERROR - Task failed with exception
Traceback (most recent call last):
  File "/home/airflow/.local/lib/python3.6/site-packages/airflow/models/taskinstance.py", line 1157, in _run_raw_task
    self._prepare_and_execute_task_with_callbacks(context, task)
  File "/home/airflow/.local/lib/python3.6/site-packages/airflow/models/taskinstance.py", line 1331, in _prepare_and_execute_task_with_callbacks
    result = self._execute_task(context, task_copy)
  File "/home/airflow/.local/lib/python3.6/site-packages/airflow/models/taskinstance.py", line 1361, in _execute_task
    result = task_copy.execute(context=context)
  File "/home/airflow/.local/lib/python3.6/site-packages/airflow/operators/python.py", line 150, in execute
    return_value = self.execute_callable()
  File "/home/airflow/.local/lib/python3.6/site-packages/airflow/operators/python.py", line 161, in execute_callable
    return self.python_callable(*self.op_args, **self.op_kwargs)
  File "/opt/airflow/dags/Staging_upload.py", line 13, in ingestionFunc
    port="6543"
  File "/home/airflow/.local/lib/python3.6/site-packages/psycopg2/__init__.py", line 122, in connect
    conn = _connect(dsn, connection_factory=connection_factory, **kwasync)
psycopg2.OperationalError: could not connect to server: Connection refused
	Is the server running on host "localhost" (::1) and accepting
	TCP/IP connections on port 6543?
could not connect to server: Connection refused
	Is the server running on host "localhost" (127.0.0.1) and accepting
	TCP/IP connections on port 6543?

[2025-06-15 16:51:56,557] {taskinstance.py:1551} INFO - Marking task as FAILED. dag_id=Job_dag, task_id=data_ingestion, execution_date=20250305T000000, start_date=20250615T165155, end_date=20250615T165156
[2025-06-15 16:51:56,730] {local_task_job.py:151} INFO - Task exited with return code 1
